<?xml version="1.0" encoding="UTF-8"?>
<robot generator="Robot 3.1.2 (Python 3.7.5 on darwin)" generated="20200121 05:48:16.714" rpa="false">
<suite id="s1" name="SearchTestSuite" source="/Users/375919/PycharmProjects/saks-ios-automation-suite/TestSuites/Search/SearchTestSuite.robot">
<test id="s1-t1" name="[Saks iOS] Search screen - HMQ-370">
<kw name="Launch Saks iOS App" library="setupenv" type="setup">
<kw name="Open Application" library="AppiumLibrary">
<doc>Opens a new application to given Appium server.
Capabilities of appium server, Android and iOS,
Please check https://github.com/appium/appium/blob/master/docs/en/writing-running-appium/server-args.md
| *Option*            | *Man.* | *Description*     |
| remote_url          | Yes    | Appium server url |
| alias               | no     | alias             |</doc>
<arguments>
<arg>${REMOTE_URL}</arg>
<arg>platformName=${PLATFORM_NAME}</arg>
<arg>platformVersion=${PLATFORM_VERSION}</arg>
<arg>deviceName=${DEVICE_NAME}</arg>
<arg>app=${APP}</arg>
<arg>automationName=${AUTOMATION_NAME}</arg>
</arguments>
<msg timestamp="20200121 05:48:18.657" level="INFO">Could not connect to port 4723 on host localhost</msg>
<msg timestamp="20200121 05:48:18.657" level="INFO">Could not get IP address for host: localhost</msg>
<msg timestamp="20200121 05:48:18.659" level="WARN">Retrying (Retry(total=2, connect=None, read=None, redirect=None, status=None)) after connection broken by 'NewConnectionError('&lt;urllib3.connection.HTTPConnection object at 0x106628f90&gt;: Failed to establish a new connection: [Errno 61] Connection refused')': /wd/hub/session</msg>
<msg timestamp="20200121 05:48:18.660" level="WARN">Retrying (Retry(total=1, connect=None, read=None, redirect=None, status=None)) after connection broken by 'NewConnectionError('&lt;urllib3.connection.HTTPConnection object at 0x116670a90&gt;: Failed to establish a new connection: [Errno 61] Connection refused')': /wd/hub/session</msg>
<msg timestamp="20200121 05:48:18.662" level="WARN">Retrying (Retry(total=0, connect=None, read=None, redirect=None, status=None)) after connection broken by 'NewConnectionError('&lt;urllib3.connection.HTTPConnection object at 0x115c72e50&gt;: Failed to establish a new connection: [Errno 61] Connection refused')': /wd/hub/session</msg>
<kw name="Capture Page Screenshot" library="AppiumLibrary">
<doc>Takes a screenshot of the current page and embeds it into the log.</doc>
<msg timestamp="20200121 05:48:18.680" level="FAIL">No application is open</msg>
<status status="FAIL" starttime="20200121 05:48:18.667" endtime="20200121 05:48:18.681"></status>
</kw>
<msg timestamp="20200121 05:48:18.694" level="WARN">Keyword 'Capture Page Screenshot' could not be run on failure: No application is open</msg>
<msg timestamp="20200121 05:48:18.705" level="FAIL">MaxRetryError: HTTPConnectionPool(host='localhost', port=4723): Max retries exceeded with url: /wd/hub/session (Caused by NewConnectionError('&lt;urllib3.connection.HTTPConnection object at 0x115c72b10&gt;: Failed to establish a new connection: [Errno 61] Connection refused'))</msg>
<status status="FAIL" starttime="20200121 05:48:18.651" endtime="20200121 05:48:18.705"></status>
</kw>
<status status="FAIL" starttime="20200121 05:48:18.651" endtime="20200121 05:48:18.706"></status>
</kw>
<kw name="Close App" library="setupenv" type="teardown">
<kw name="Close All Applications" library="AppiumLibrary">
<doc>Closes all open applications.</doc>
<status status="PASS" starttime="20200121 05:48:18.707" endtime="20200121 05:48:18.726"></status>
</kw>
<status status="PASS" starttime="20200121 05:48:18.707" endtime="20200121 05:48:18.727"></status>
</kw>
<tags>
<tag>Example</tag>
<tag>Validated</tag>
</tags>
<status status="FAIL" starttime="20200121 05:48:18.650" endtime="20200121 05:48:18.727" critical="yes">Setup failed:
MaxRetryError: HTTPConnectionPool(host='localhost', port=4723): Max retries exceeded with url: /wd/hub/session (Caused by NewConnectionError('&lt;urllib3.connection.HTTPConnection object at 0x115c72b10&gt;: Failed to establish a new connection: [Errno 61] Connection refused'))</status>
</test>
<doc>Test suite to verify Search test cases</doc>
<status status="FAIL" starttime="20200121 05:48:16.715" endtime="20200121 05:48:18.728"></status>
</suite>
<statistics>
<total>
<stat pass="0" fail="1">Critical Tests</stat>
<stat pass="0" fail="1">All Tests</stat>
</total>
<tag>
<stat pass="0" fail="1">Example</stat>
<stat pass="0" fail="1">Validated</stat>
</tag>
<suite>
<stat pass="0" fail="1" id="s1" name="SearchTestSuite">SearchTestSuite</stat>
</suite>
</statistics>
<errors>
<msg timestamp="20200121 05:48:18.362" level="ERROR">Error in file '/Users/375919/PycharmProjects/saks-ios-automation-suite/Locators/Search/search_locators.robot': Setting variable '${SEARCH_LOC_ADDEDTOBAG} id=ADDED TO BAG' failed: Invalid variable name '${SEARCH_LOC_ADDEDTOBAG} id=ADDED TO BAG'.</msg>
<msg timestamp="20200121 05:48:18.659" level="WARN">Retrying (Retry(total=2, connect=None, read=None, redirect=None, status=None)) after connection broken by 'NewConnectionError('&lt;urllib3.connection.HTTPConnection object at 0x106628f90&gt;: Failed to establish a new connection: [Errno 61] Connection refused')': /wd/hub/session</msg>
<msg timestamp="20200121 05:48:18.660" level="WARN">Retrying (Retry(total=1, connect=None, read=None, redirect=None, status=None)) after connection broken by 'NewConnectionError('&lt;urllib3.connection.HTTPConnection object at 0x116670a90&gt;: Failed to establish a new connection: [Errno 61] Connection refused')': /wd/hub/session</msg>
<msg timestamp="20200121 05:48:18.662" level="WARN">Retrying (Retry(total=0, connect=None, read=None, redirect=None, status=None)) after connection broken by 'NewConnectionError('&lt;urllib3.connection.HTTPConnection object at 0x115c72e50&gt;: Failed to establish a new connection: [Errno 61] Connection refused')': /wd/hub/session</msg>
<msg timestamp="20200121 05:48:18.694" level="WARN">Keyword 'Capture Page Screenshot' could not be run on failure: No application is open</msg>
</errors>
</robot>
